[2023-05-27T20:38:07.929+0000] {taskinstance.py:1083} INFO - Dependencies all met for <TaskInstance: captura_dados.captura_dados_task manual__2023-05-27T20:26:17.645334+00:00 [queued]>
[2023-05-27T20:38:07.941+0000] {taskinstance.py:1083} INFO - Dependencies all met for <TaskInstance: captura_dados.captura_dados_task manual__2023-05-27T20:26:17.645334+00:00 [queued]>
[2023-05-27T20:38:07.941+0000] {taskinstance.py:1279} INFO - 
--------------------------------------------------------------------------------
[2023-05-27T20:38:07.941+0000] {taskinstance.py:1280} INFO - Starting attempt 5 of 5
[2023-05-27T20:38:07.941+0000] {taskinstance.py:1281} INFO - 
--------------------------------------------------------------------------------
[2023-05-27T20:38:07.957+0000] {taskinstance.py:1300} INFO - Executing <Task(PythonOperator): captura_dados_task> on 2023-05-27 20:26:17.645334+00:00
[2023-05-27T20:38:07.963+0000] {standard_task_runner.py:55} INFO - Started process 1400 to run task
[2023-05-27T20:38:07.968+0000] {standard_task_runner.py:82} INFO - Running: ['***', 'tasks', 'run', 'captura_dados', 'captura_dados_task', 'manual__2023-05-27T20:26:17.645334+00:00', '--job-id', '287', '--raw', '--subdir', 'DAGS_FOLDER/captura_dados.py', '--cfg-path', '/tmp/tmpvykd7zf6']
[2023-05-27T20:38:07.969+0000] {standard_task_runner.py:83} INFO - Job 287: Subtask captura_dados_task
[2023-05-27T20:38:08.059+0000] {task_command.py:388} INFO - Running <TaskInstance: captura_dados.captura_dados_task manual__2023-05-27T20:26:17.645334+00:00 [running]> on host c7c762ba6b48
[2023-05-27T20:38:08.211+0000] {taskinstance.py:1509} INFO - Exporting the following env vars:
AIRFLOW_CTX_DAG_EMAIL=test@test.com
AIRFLOW_CTX_DAG_OWNER=***
AIRFLOW_CTX_DAG_ID=captura_dados
AIRFLOW_CTX_TASK_ID=captura_dados_task
AIRFLOW_CTX_EXECUTION_DATE=2023-05-27T20:26:17.645334+00:00
AIRFLOW_CTX_TRY_NUMBER=5
AIRFLOW_CTX_DAG_RUN_ID=manual__2023-05-27T20:26:17.645334+00:00
[2023-05-27T20:38:08.738+0000] {taskinstance.py:1768} ERROR - Task failed with exception
Traceback (most recent call last):
  File "/home/airflow/.local/lib/python3.7/site-packages/airflow/operators/python.py", line 175, in execute
    return_value = self.execute_callable()
  File "/home/airflow/.local/lib/python3.7/site-packages/airflow/operators/python.py", line 192, in execute_callable
    return self.python_callable(*self.op_args, **self.op_kwargs)
  File "/opt/airflow/dags/captura_dados.py", line 12, in download_arquivo
    with open('/home/michel/airflow-docker/dags/brazilian-ecommerce.zip', 'wb') as file:
FileNotFoundError: [Errno 2] No such file or directory: '/home/michel/airflow-docker/dags/brazilian-ecommerce.zip'
[2023-05-27T20:38:08.751+0000] {taskinstance.py:1323} INFO - Marking task as FAILED. dag_id=captura_dados, task_id=captura_dados_task, execution_date=20230527T202617, start_date=20230527T203807, end_date=20230527T203808
[2023-05-27T20:38:08.770+0000] {standard_task_runner.py:105} ERROR - Failed to execute job 287 for task captura_dados_task ([Errno 2] No such file or directory: '/home/michel/airflow-docker/dags/brazilian-ecommerce.zip'; 1400)
[2023-05-27T20:38:08.830+0000] {local_task_job.py:208} INFO - Task exited with return code 1
[2023-05-27T20:38:08.868+0000] {taskinstance.py:2578} INFO - 0 downstream tasks scheduled from follow-on schedule check
