[2023-05-27T17:53:54.767+0000] {taskinstance.py:1083} INFO - Dependencies all met for <TaskInstance: captura_dados.captura_dados manual__2023-05-27T17:36:14.242333+00:00 [queued]>
[2023-05-27T17:53:54.776+0000] {taskinstance.py:1083} INFO - Dependencies all met for <TaskInstance: captura_dados.captura_dados manual__2023-05-27T17:36:14.242333+00:00 [queued]>
[2023-05-27T17:53:54.776+0000] {taskinstance.py:1279} INFO - 
--------------------------------------------------------------------------------
[2023-05-27T17:53:54.776+0000] {taskinstance.py:1280} INFO - Starting attempt 5 of 5
[2023-05-27T17:53:54.777+0000] {taskinstance.py:1281} INFO - 
--------------------------------------------------------------------------------
[2023-05-27T17:53:54.796+0000] {taskinstance.py:1300} INFO - Executing <Task(PythonOperator): captura_dados> on 2023-05-27 17:36:14.242333+00:00
[2023-05-27T17:53:54.801+0000] {standard_task_runner.py:55} INFO - Started process 1111 to run task
[2023-05-27T17:53:54.804+0000] {standard_task_runner.py:82} INFO - Running: ['***', 'tasks', 'run', 'captura_dados', 'captura_dados', 'manual__2023-05-27T17:36:14.242333+00:00', '--job-id', '158', '--raw', '--subdir', 'DAGS_FOLDER/captura_dados.py', '--cfg-path', '/tmp/tmp58manqm9']
[2023-05-27T17:53:54.804+0000] {standard_task_runner.py:83} INFO - Job 158: Subtask captura_dados
[2023-05-27T17:53:54.860+0000] {task_command.py:388} INFO - Running <TaskInstance: captura_dados.captura_dados manual__2023-05-27T17:36:14.242333+00:00 [running]> on host df5a7ad10ac6
[2023-05-27T17:53:54.986+0000] {taskinstance.py:1509} INFO - Exporting the following env vars:
AIRFLOW_CTX_DAG_EMAIL=test@test.com
AIRFLOW_CTX_DAG_OWNER=***
AIRFLOW_CTX_DAG_ID=captura_dados
AIRFLOW_CTX_TASK_ID=captura_dados
AIRFLOW_CTX_EXECUTION_DATE=2023-05-27T17:36:14.242333+00:00
AIRFLOW_CTX_TRY_NUMBER=5
AIRFLOW_CTX_DAG_RUN_ID=manual__2023-05-27T17:36:14.242333+00:00
[2023-05-27T17:53:54.987+0000] {taskinstance.py:1768} ERROR - Task failed with exception
Traceback (most recent call last):
  File "/home/airflow/.local/lib/python3.7/site-packages/airflow/operators/python.py", line 175, in execute
    return_value = self.execute_callable()
  File "/home/airflow/.local/lib/python3.7/site-packages/airflow/operators/python.py", line 192, in execute_callable
    return self.python_callable(*self.op_args, **self.op_kwargs)
  File "/opt/airflow/dags/captura_dados.py", line 30, in captura_dados
    cookies = requests.cookies.get_dict()
AttributeError: module 'requests.cookies' has no attribute 'get_dict'
[2023-05-27T17:53:55.004+0000] {taskinstance.py:1323} INFO - Marking task as FAILED. dag_id=captura_dados, task_id=captura_dados, execution_date=20230527T173614, start_date=20230527T175354, end_date=20230527T175355
[2023-05-27T17:53:55.034+0000] {standard_task_runner.py:105} ERROR - Failed to execute job 158 for task captura_dados (module 'requests.cookies' has no attribute 'get_dict'; 1111)
[2023-05-27T17:53:55.058+0000] {local_task_job.py:208} INFO - Task exited with return code 1
[2023-05-27T17:53:55.089+0000] {taskinstance.py:2578} INFO - 0 downstream tasks scheduled from follow-on schedule check
