[2023-05-27T18:24:05.389+0000] {taskinstance.py:1083} INFO - Dependencies all met for <TaskInstance: captura_dados.extract_zip_file manual__2023-05-27T18:19:19.145234+00:00 [queued]>
[2023-05-27T18:24:05.404+0000] {taskinstance.py:1083} INFO - Dependencies all met for <TaskInstance: captura_dados.extract_zip_file manual__2023-05-27T18:19:19.145234+00:00 [queued]>
[2023-05-27T18:24:05.404+0000] {taskinstance.py:1279} INFO - 
--------------------------------------------------------------------------------
[2023-05-27T18:24:05.404+0000] {taskinstance.py:1280} INFO - Starting attempt 7 of 8
[2023-05-27T18:24:05.404+0000] {taskinstance.py:1281} INFO - 
--------------------------------------------------------------------------------
[2023-05-27T18:24:05.424+0000] {taskinstance.py:1300} INFO - Executing <Task(PythonOperator): extract_zip_file> on 2023-05-27 18:19:19.145234+00:00
[2023-05-27T18:24:05.434+0000] {standard_task_runner.py:55} INFO - Started process 2894 to run task
[2023-05-27T18:24:05.437+0000] {standard_task_runner.py:82} INFO - Running: ['***', 'tasks', 'run', 'captura_dados', 'extract_zip_file', 'manual__2023-05-27T18:19:19.145234+00:00', '--job-id', '182', '--raw', '--subdir', 'DAGS_FOLDER/captura_dados.py', '--cfg-path', '/tmp/tmpbdkupia7']
[2023-05-27T18:24:05.438+0000] {standard_task_runner.py:83} INFO - Job 182: Subtask extract_zip_file
[2023-05-27T18:24:05.518+0000] {task_command.py:388} INFO - Running <TaskInstance: captura_dados.extract_zip_file manual__2023-05-27T18:19:19.145234+00:00 [running]> on host df5a7ad10ac6
[2023-05-27T18:24:05.597+0000] {taskinstance.py:1509} INFO - Exporting the following env vars:
AIRFLOW_CTX_DAG_EMAIL=test@test.com
AIRFLOW_CTX_DAG_OWNER=***
AIRFLOW_CTX_DAG_ID=captura_dados
AIRFLOW_CTX_TASK_ID=extract_zip_file
AIRFLOW_CTX_EXECUTION_DATE=2023-05-27T18:19:19.145234+00:00
AIRFLOW_CTX_TRY_NUMBER=7
AIRFLOW_CTX_DAG_RUN_ID=manual__2023-05-27T18:19:19.145234+00:00
[2023-05-27T18:24:05.598+0000] {taskinstance.py:1768} ERROR - Task failed with exception
Traceback (most recent call last):
  File "/home/airflow/.local/lib/python3.7/site-packages/airflow/operators/python.py", line 175, in execute
    return_value = self.execute_callable()
  File "/home/airflow/.local/lib/python3.7/site-packages/airflow/operators/python.py", line 192, in execute_callable
    return self.python_callable(*self.op_args, **self.op_kwargs)
  File "/opt/airflow/dags/captura_dados.py", line 23, in extract_zip_file
    with zipfile.ZipFile(file_path, 'r') as zip_ref:
  File "/usr/local/lib/python3.7/zipfile.py", line 1258, in __init__
    self._RealGetContents()
  File "/usr/local/lib/python3.7/zipfile.py", line 1325, in _RealGetContents
    raise BadZipFile("File is not a zip file")
zipfile.BadZipFile: File is not a zip file
[2023-05-27T18:24:05.607+0000] {taskinstance.py:1323} INFO - Marking task as UP_FOR_RETRY. dag_id=captura_dados, task_id=extract_zip_file, execution_date=20230527T181919, start_date=20230527T182405, end_date=20230527T182405
[2023-05-27T18:24:05.620+0000] {standard_task_runner.py:105} ERROR - Failed to execute job 182 for task extract_zip_file (File is not a zip file; 2894)
[2023-05-27T18:24:05.649+0000] {local_task_job.py:208} INFO - Task exited with return code 1
[2023-05-27T18:24:05.665+0000] {taskinstance.py:2578} INFO - 0 downstream tasks scheduled from follow-on schedule check
