[2023-05-27T18:24:16.753+0000] {taskinstance.py:1083} INFO - Dependencies all met for <TaskInstance: captura_dados.extract_zip_file manual__2023-05-27T18:19:19.145234+00:00 [queued]>
[2023-05-27T18:24:16.762+0000] {taskinstance.py:1083} INFO - Dependencies all met for <TaskInstance: captura_dados.extract_zip_file manual__2023-05-27T18:19:19.145234+00:00 [queued]>
[2023-05-27T18:24:16.763+0000] {taskinstance.py:1279} INFO - 
--------------------------------------------------------------------------------
[2023-05-27T18:24:16.763+0000] {taskinstance.py:1280} INFO - Starting attempt 8 of 8
[2023-05-27T18:24:16.763+0000] {taskinstance.py:1281} INFO - 
--------------------------------------------------------------------------------
[2023-05-27T18:24:16.777+0000] {taskinstance.py:1300} INFO - Executing <Task(PythonOperator): extract_zip_file> on 2023-05-27 18:19:19.145234+00:00
[2023-05-27T18:24:16.784+0000] {standard_task_runner.py:55} INFO - Started process 2909 to run task
[2023-05-27T18:24:16.788+0000] {standard_task_runner.py:82} INFO - Running: ['***', 'tasks', 'run', 'captura_dados', 'extract_zip_file', 'manual__2023-05-27T18:19:19.145234+00:00', '--job-id', '183', '--raw', '--subdir', 'DAGS_FOLDER/captura_dados.py', '--cfg-path', '/tmp/tmp802uy0ts']
[2023-05-27T18:24:16.790+0000] {standard_task_runner.py:83} INFO - Job 183: Subtask extract_zip_file
[2023-05-27T18:24:16.850+0000] {task_command.py:388} INFO - Running <TaskInstance: captura_dados.extract_zip_file manual__2023-05-27T18:19:19.145234+00:00 [running]> on host df5a7ad10ac6
[2023-05-27T18:24:16.922+0000] {taskinstance.py:1509} INFO - Exporting the following env vars:
AIRFLOW_CTX_DAG_EMAIL=test@test.com
AIRFLOW_CTX_DAG_OWNER=***
AIRFLOW_CTX_DAG_ID=captura_dados
AIRFLOW_CTX_TASK_ID=extract_zip_file
AIRFLOW_CTX_EXECUTION_DATE=2023-05-27T18:19:19.145234+00:00
AIRFLOW_CTX_TRY_NUMBER=8
AIRFLOW_CTX_DAG_RUN_ID=manual__2023-05-27T18:19:19.145234+00:00
[2023-05-27T18:24:16.923+0000] {taskinstance.py:1768} ERROR - Task failed with exception
Traceback (most recent call last):
  File "/home/airflow/.local/lib/python3.7/site-packages/airflow/operators/python.py", line 175, in execute
    return_value = self.execute_callable()
  File "/home/airflow/.local/lib/python3.7/site-packages/airflow/operators/python.py", line 192, in execute_callable
    return self.python_callable(*self.op_args, **self.op_kwargs)
  File "/opt/airflow/dags/captura_dados.py", line 23, in extract_zip_file
    with zipfile.ZipFile(file_path, 'r') as zip_ref:
  File "/usr/local/lib/python3.7/zipfile.py", line 1258, in __init__
    self._RealGetContents()
  File "/usr/local/lib/python3.7/zipfile.py", line 1325, in _RealGetContents
    raise BadZipFile("File is not a zip file")
zipfile.BadZipFile: File is not a zip file
[2023-05-27T18:24:16.932+0000] {taskinstance.py:1323} INFO - Marking task as FAILED. dag_id=captura_dados, task_id=extract_zip_file, execution_date=20230527T181919, start_date=20230527T182416, end_date=20230527T182416
[2023-05-27T18:24:16.948+0000] {standard_task_runner.py:105} ERROR - Failed to execute job 183 for task extract_zip_file (File is not a zip file; 2909)
[2023-05-27T18:24:16.959+0000] {local_task_job.py:208} INFO - Task exited with return code 1
[2023-05-27T18:24:16.985+0000] {taskinstance.py:2578} INFO - 0 downstream tasks scheduled from follow-on schedule check
