[2023-05-31T02:19:34.748+0000] {taskinstance.py:1083} INFO - Dependencies all met for <TaskInstance: captura_dados.created_folders_task manual__2023-05-31T01:40:46.166777+00:00 [queued]>
[2023-05-31T02:19:34.762+0000] {taskinstance.py:1083} INFO - Dependencies all met for <TaskInstance: captura_dados.created_folders_task manual__2023-05-31T01:40:46.166777+00:00 [queued]>
[2023-05-31T02:19:34.763+0000] {taskinstance.py:1279} INFO - 
--------------------------------------------------------------------------------
[2023-05-31T02:19:34.763+0000] {taskinstance.py:1280} INFO - Starting attempt 19 of 19
[2023-05-31T02:19:34.763+0000] {taskinstance.py:1281} INFO - 
--------------------------------------------------------------------------------
[2023-05-31T02:19:34.787+0000] {taskinstance.py:1300} INFO - Executing <Task(PythonOperator): created_folders_task> on 2023-05-31 01:40:46.166777+00:00
[2023-05-31T02:19:34.796+0000] {standard_task_runner.py:55} INFO - Started process 2568 to run task
[2023-05-31T02:19:34.802+0000] {standard_task_runner.py:82} INFO - Running: ['***', 'tasks', 'run', 'captura_dados', 'created_folders_task', 'manual__2023-05-31T01:40:46.166777+00:00', '--job-id', '63', '--raw', '--subdir', 'DAGS_FOLDER/captura_dados.py', '--cfg-path', '/tmp/tmpmn65f5fm']
[2023-05-31T02:19:34.804+0000] {standard_task_runner.py:83} INFO - Job 63: Subtask created_folders_task
[2023-05-31T02:19:34.890+0000] {task_command.py:388} INFO - Running <TaskInstance: captura_dados.created_folders_task manual__2023-05-31T01:40:46.166777+00:00 [running]> on host 5219a5ad576c
[2023-05-31T02:19:34.993+0000] {taskinstance.py:1509} INFO - Exporting the following env vars:
AIRFLOW_CTX_DAG_EMAIL=test@test.com
AIRFLOW_CTX_DAG_OWNER=***
AIRFLOW_CTX_DAG_ID=captura_dados
AIRFLOW_CTX_TASK_ID=created_folders_task
AIRFLOW_CTX_EXECUTION_DATE=2023-05-31T01:40:46.166777+00:00
AIRFLOW_CTX_TRY_NUMBER=19
AIRFLOW_CTX_DAG_RUN_ID=manual__2023-05-31T01:40:46.166777+00:00
[2023-05-31T02:19:34.997+0000] {taskinstance.py:1768} ERROR - Task failed with exception
Traceback (most recent call last):
  File "/home/airflow/.local/lib/python3.7/site-packages/airflow/operators/python.py", line 175, in execute
    return_value = self.execute_callable()
  File "/home/airflow/.local/lib/python3.7/site-packages/airflow/operators/python.py", line 192, in execute_callable
    return self.python_callable(*self.op_args, **self.op_kwargs)
  File "/opt/airflow/dags/captura_dados.py", line 19, in created_folders
    df = pd.read_csv(csv_file_path)
  File "/home/airflow/.local/lib/python3.7/site-packages/pandas/util/_decorators.py", line 311, in wrapper
    return func(*args, **kwargs)
  File "/home/airflow/.local/lib/python3.7/site-packages/pandas/io/parsers/readers.py", line 586, in read_csv
    return _read(filepath_or_buffer, kwds)
  File "/home/airflow/.local/lib/python3.7/site-packages/pandas/io/parsers/readers.py", line 482, in _read
    parser = TextFileReader(filepath_or_buffer, **kwds)
  File "/home/airflow/.local/lib/python3.7/site-packages/pandas/io/parsers/readers.py", line 811, in __init__
    self._engine = self._make_engine(self.engine)
  File "/home/airflow/.local/lib/python3.7/site-packages/pandas/io/parsers/readers.py", line 1040, in _make_engine
    return mapping[engine](self.f, **self.options)  # type: ignore[call-arg]
  File "/home/airflow/.local/lib/python3.7/site-packages/pandas/io/parsers/c_parser_wrapper.py", line 51, in __init__
    self._open_handles(src, kwds)
  File "/home/airflow/.local/lib/python3.7/site-packages/pandas/io/parsers/base_parser.py", line 229, in _open_handles
    errors=kwds.get("encoding_errors", "strict"),
  File "/home/airflow/.local/lib/python3.7/site-packages/pandas/io/common.py", line 707, in get_handle
    newline="",
FileNotFoundError: [Errno 2] No such file or directory: '/home/michel/Documentos/olist_brasil/airflow-docker/dags/nome_diretorios.csv'
[2023-05-31T02:19:35.009+0000] {taskinstance.py:1323} INFO - Marking task as FAILED. dag_id=captura_dados, task_id=created_folders_task, execution_date=20230531T014046, start_date=20230531T021934, end_date=20230531T021935
[2023-05-31T02:19:35.030+0000] {standard_task_runner.py:105} ERROR - Failed to execute job 63 for task created_folders_task ([Errno 2] No such file or directory: '/home/michel/Documentos/olist_brasil/airflow-docker/dags/nome_diretorios.csv'; 2568)
[2023-05-31T02:19:35.052+0000] {local_task_job.py:208} INFO - Task exited with return code 1
[2023-05-31T02:19:35.076+0000] {taskinstance.py:2578} INFO - 0 downstream tasks scheduled from follow-on schedule check
