[2023-05-31T02:22:10.011+0000] {taskinstance.py:1083} INFO - Dependencies all met for <TaskInstance: captura_dados.created_folders_task manual__2023-05-31T02:21:55.090685+00:00 [queued]>
[2023-05-31T02:22:10.024+0000] {taskinstance.py:1083} INFO - Dependencies all met for <TaskInstance: captura_dados.created_folders_task manual__2023-05-31T02:21:55.090685+00:00 [queued]>
[2023-05-31T02:22:10.025+0000] {taskinstance.py:1279} INFO - 
--------------------------------------------------------------------------------
[2023-05-31T02:22:10.025+0000] {taskinstance.py:1280} INFO - Starting attempt 2 of 2
[2023-05-31T02:22:10.025+0000] {taskinstance.py:1281} INFO - 
--------------------------------------------------------------------------------
[2023-05-31T02:22:10.046+0000] {taskinstance.py:1300} INFO - Executing <Task(PythonOperator): created_folders_task> on 2023-05-31 02:21:55.090685+00:00
[2023-05-31T02:22:10.053+0000] {standard_task_runner.py:55} INFO - Started process 2720 to run task
[2023-05-31T02:22:10.057+0000] {standard_task_runner.py:82} INFO - Running: ['***', 'tasks', 'run', 'captura_dados', 'created_folders_task', 'manual__2023-05-31T02:21:55.090685+00:00', '--job-id', '68', '--raw', '--subdir', 'DAGS_FOLDER/captura_dados.py', '--cfg-path', '/tmp/tmpmr9bnqr3']
[2023-05-31T02:22:10.059+0000] {standard_task_runner.py:83} INFO - Job 68: Subtask created_folders_task
[2023-05-31T02:22:10.136+0000] {task_command.py:388} INFO - Running <TaskInstance: captura_dados.created_folders_task manual__2023-05-31T02:21:55.090685+00:00 [running]> on host 5219a5ad576c
[2023-05-31T02:22:10.235+0000] {taskinstance.py:1509} INFO - Exporting the following env vars:
AIRFLOW_CTX_DAG_EMAIL=test@test.com
AIRFLOW_CTX_DAG_OWNER=***
AIRFLOW_CTX_DAG_ID=captura_dados
AIRFLOW_CTX_TASK_ID=created_folders_task
AIRFLOW_CTX_EXECUTION_DATE=2023-05-31T02:21:55.090685+00:00
AIRFLOW_CTX_TRY_NUMBER=2
AIRFLOW_CTX_DAG_RUN_ID=manual__2023-05-31T02:21:55.090685+00:00
[2023-05-31T02:22:10.236+0000] {logging_mixin.py:137} INFO - Pasta data j√° existe!
[2023-05-31T02:22:10.238+0000] {taskinstance.py:1768} ERROR - Task failed with exception
Traceback (most recent call last):
  File "/home/airflow/.local/lib/python3.7/site-packages/airflow/operators/python.py", line 175, in execute
    return_value = self.execute_callable()
  File "/home/airflow/.local/lib/python3.7/site-packages/airflow/operators/python.py", line 192, in execute_callable
    return self.python_callable(*self.op_args, **self.op_kwargs)
  File "/opt/airflow/dags/captura_dados.py", line 28, in created_folders
    df = pd.read_csv(csv_file_path)
  File "/home/airflow/.local/lib/python3.7/site-packages/pandas/util/_decorators.py", line 311, in wrapper
    return func(*args, **kwargs)
  File "/home/airflow/.local/lib/python3.7/site-packages/pandas/io/parsers/readers.py", line 586, in read_csv
    return _read(filepath_or_buffer, kwds)
  File "/home/airflow/.local/lib/python3.7/site-packages/pandas/io/parsers/readers.py", line 482, in _read
    parser = TextFileReader(filepath_or_buffer, **kwds)
  File "/home/airflow/.local/lib/python3.7/site-packages/pandas/io/parsers/readers.py", line 811, in __init__
    self._engine = self._make_engine(self.engine)
  File "/home/airflow/.local/lib/python3.7/site-packages/pandas/io/parsers/readers.py", line 1040, in _make_engine
    return mapping[engine](self.f, **self.options)  # type: ignore[call-arg]
  File "/home/airflow/.local/lib/python3.7/site-packages/pandas/io/parsers/c_parser_wrapper.py", line 51, in __init__
    self._open_handles(src, kwds)
  File "/home/airflow/.local/lib/python3.7/site-packages/pandas/io/parsers/base_parser.py", line 229, in _open_handles
    errors=kwds.get("encoding_errors", "strict"),
  File "/home/airflow/.local/lib/python3.7/site-packages/pandas/io/common.py", line 707, in get_handle
    newline="",
IsADirectoryError: [Errno 21] Is a directory: '/opt/airflow'
[2023-05-31T02:22:10.246+0000] {taskinstance.py:1323} INFO - Marking task as FAILED. dag_id=captura_dados, task_id=created_folders_task, execution_date=20230531T022155, start_date=20230531T022210, end_date=20230531T022210
[2023-05-31T02:22:10.258+0000] {standard_task_runner.py:105} ERROR - Failed to execute job 68 for task created_folders_task ([Errno 21] Is a directory: '/opt/airflow'; 2720)
[2023-05-31T02:22:10.273+0000] {local_task_job.py:208} INFO - Task exited with return code 1
[2023-05-31T02:22:10.299+0000] {taskinstance.py:2578} INFO - 0 downstream tasks scheduled from follow-on schedule check
