[2023-05-31T02:55:43.770+0000] {taskinstance.py:1083} INFO - Dependencies all met for <TaskInstance: captura_dados.created_folders_task manual__2023-05-31T02:51:06.057496+00:00 [queued]>
[2023-05-31T02:55:43.787+0000] {taskinstance.py:1083} INFO - Dependencies all met for <TaskInstance: captura_dados.created_folders_task manual__2023-05-31T02:51:06.057496+00:00 [queued]>
[2023-05-31T02:55:43.787+0000] {taskinstance.py:1279} INFO - 
--------------------------------------------------------------------------------
[2023-05-31T02:55:43.788+0000] {taskinstance.py:1280} INFO - Starting attempt 2 of 3
[2023-05-31T02:55:43.788+0000] {taskinstance.py:1281} INFO - 
--------------------------------------------------------------------------------
[2023-05-31T02:55:43.809+0000] {taskinstance.py:1300} INFO - Executing <Task(PythonOperator): created_folders_task> on 2023-05-31 02:51:06.057496+00:00
[2023-05-31T02:55:43.819+0000] {standard_task_runner.py:55} INFO - Started process 128 to run task
[2023-05-31T02:55:43.823+0000] {standard_task_runner.py:82} INFO - Running: ['***', 'tasks', 'run', 'captura_dados', 'created_folders_task', 'manual__2023-05-31T02:51:06.057496+00:00', '--job-id', '112', '--raw', '--subdir', 'DAGS_FOLDER/captura_dados.py', '--cfg-path', '/tmp/tmpyygwlqa6']
[2023-05-31T02:55:43.827+0000] {standard_task_runner.py:83} INFO - Job 112: Subtask created_folders_task
[2023-05-31T02:55:43.928+0000] {task_command.py:388} INFO - Running <TaskInstance: captura_dados.created_folders_task manual__2023-05-31T02:51:06.057496+00:00 [running]> on host 0de0741c404d
[2023-05-31T02:55:44.035+0000] {taskinstance.py:1509} INFO - Exporting the following env vars:
AIRFLOW_CTX_DAG_EMAIL=test@test.com
AIRFLOW_CTX_DAG_OWNER=***
AIRFLOW_CTX_DAG_ID=captura_dados
AIRFLOW_CTX_TASK_ID=created_folders_task
AIRFLOW_CTX_EXECUTION_DATE=2023-05-31T02:51:06.057496+00:00
AIRFLOW_CTX_TRY_NUMBER=2
AIRFLOW_CTX_DAG_RUN_ID=manual__2023-05-31T02:51:06.057496+00:00
[2023-05-31T02:55:44.043+0000] {taskinstance.py:1768} ERROR - Task failed with exception
Traceback (most recent call last):
  File "/home/airflow/.local/lib/python3.7/site-packages/airflow/operators/python.py", line 175, in execute
    return_value = self.execute_callable()
  File "/home/airflow/.local/lib/python3.7/site-packages/airflow/operators/python.py", line 192, in execute_callable
    return self.python_callable(*self.op_args, **self.op_kwargs)
  File "/opt/airflow/dags/captura_dados.py", line 24, in created_folders
    os.makedirs('data')
  File "/usr/local/lib/python3.7/os.py", line 223, in makedirs
    mkdir(name, mode)
FileExistsError: [Errno 17] File exists: 'data'
[2023-05-31T02:55:44.055+0000] {taskinstance.py:1323} INFO - Marking task as UP_FOR_RETRY. dag_id=captura_dados, task_id=created_folders_task, execution_date=20230531T025106, start_date=20230531T025543, end_date=20230531T025544
[2023-05-31T02:55:44.069+0000] {standard_task_runner.py:105} ERROR - Failed to execute job 112 for task created_folders_task ([Errno 17] File exists: 'data'; 128)
[2023-05-31T02:55:44.116+0000] {local_task_job.py:208} INFO - Task exited with return code 1
[2023-05-31T02:55:44.135+0000] {taskinstance.py:2578} INFO - 0 downstream tasks scheduled from follow-on schedule check
