[2023-05-27T21:22:49.206+0000] {taskinstance.py:1083} INFO - Dependencies all met for <TaskInstance: captura_dados.captura_dados_task manual__2023-05-27T21:22:47.874684+00:00 [queued]>
[2023-05-27T21:22:49.243+0000] {taskinstance.py:1083} INFO - Dependencies all met for <TaskInstance: captura_dados.captura_dados_task manual__2023-05-27T21:22:47.874684+00:00 [queued]>
[2023-05-27T21:22:49.243+0000] {taskinstance.py:1279} INFO - 
--------------------------------------------------------------------------------
[2023-05-27T21:22:49.243+0000] {taskinstance.py:1280} INFO - Starting attempt 1 of 2
[2023-05-27T21:22:49.243+0000] {taskinstance.py:1281} INFO - 
--------------------------------------------------------------------------------
[2023-05-27T21:22:49.263+0000] {taskinstance.py:1300} INFO - Executing <Task(PythonOperator): captura_dados_task> on 2023-05-27 21:22:47.874684+00:00
[2023-05-27T21:22:49.270+0000] {standard_task_runner.py:55} INFO - Started process 136 to run task
[2023-05-27T21:22:49.274+0000] {standard_task_runner.py:82} INFO - Running: ['***', 'tasks', 'run', 'captura_dados', 'captura_dados_task', 'manual__2023-05-27T21:22:47.874684+00:00', '--job-id', '301', '--raw', '--subdir', 'DAGS_FOLDER/captura_dados.py', '--cfg-path', '/tmp/tmpqht80eon']
[2023-05-27T21:22:49.274+0000] {standard_task_runner.py:83} INFO - Job 301: Subtask captura_dados_task
[2023-05-27T21:22:49.345+0000] {task_command.py:388} INFO - Running <TaskInstance: captura_dados.captura_dados_task manual__2023-05-27T21:22:47.874684+00:00 [running]> on host 33030ed3903b
[2023-05-27T21:22:49.431+0000] {taskinstance.py:1509} INFO - Exporting the following env vars:
AIRFLOW_CTX_DAG_EMAIL=test@test.com
AIRFLOW_CTX_DAG_OWNER=***
AIRFLOW_CTX_DAG_ID=captura_dados
AIRFLOW_CTX_TASK_ID=captura_dados_task
AIRFLOW_CTX_EXECUTION_DATE=2023-05-27T21:22:47.874684+00:00
AIRFLOW_CTX_TRY_NUMBER=1
AIRFLOW_CTX_DAG_RUN_ID=manual__2023-05-27T21:22:47.874684+00:00
[2023-05-27T21:22:50.428+0000] {taskinstance.py:1768} ERROR - Task failed with exception
Traceback (most recent call last):
  File "/home/airflow/.local/lib/python3.7/site-packages/airflow/operators/python.py", line 175, in execute
    return_value = self.execute_callable()
  File "/home/airflow/.local/lib/python3.7/site-packages/airflow/operators/python.py", line 192, in execute_callable
    return self.python_callable(*self.op_args, **self.op_kwargs)
  File "/opt/airflow/dags/captura_dados.py", line 12, in download_arquivo
    urllib.request.urlretrieve(url, output_file)
  File "/usr/local/lib/python3.7/urllib/request.py", line 257, in urlretrieve
    tfp = open(filename, 'wb')
FileNotFoundError: [Errno 2] No such file or directory: '/home/michel/airflow-docker/data/transient/brazilian-ecommerce.zip'
[2023-05-27T21:22:50.438+0000] {taskinstance.py:1323} INFO - Marking task as UP_FOR_RETRY. dag_id=captura_dados, task_id=captura_dados_task, execution_date=20230527T212247, start_date=20230527T212249, end_date=20230527T212250
[2023-05-27T21:22:50.453+0000] {standard_task_runner.py:105} ERROR - Failed to execute job 301 for task captura_dados_task ([Errno 2] No such file or directory: '/home/michel/airflow-docker/data/transient/brazilian-ecommerce.zip'; 136)
[2023-05-27T21:22:50.490+0000] {local_task_job.py:208} INFO - Task exited with return code 1
[2023-05-27T21:22:50.529+0000] {taskinstance.py:2578} INFO - 0 downstream tasks scheduled from follow-on schedule check
