[2023-05-31T02:23:29.045+0000] {taskinstance.py:1083} INFO - Dependencies all met for <TaskInstance: captura_dados.created_folders_task manual__2023-05-31T02:23:14.458005+00:00 [queued]>
[2023-05-31T02:23:29.060+0000] {taskinstance.py:1083} INFO - Dependencies all met for <TaskInstance: captura_dados.created_folders_task manual__2023-05-31T02:23:14.458005+00:00 [queued]>
[2023-05-31T02:23:29.060+0000] {taskinstance.py:1279} INFO - 
--------------------------------------------------------------------------------
[2023-05-31T02:23:29.060+0000] {taskinstance.py:1280} INFO - Starting attempt 2 of 2
[2023-05-31T02:23:29.060+0000] {taskinstance.py:1281} INFO - 
--------------------------------------------------------------------------------
[2023-05-31T02:23:29.084+0000] {taskinstance.py:1300} INFO - Executing <Task(PythonOperator): created_folders_task> on 2023-05-31 02:23:14.458005+00:00
[2023-05-31T02:23:29.093+0000] {standard_task_runner.py:55} INFO - Started process 2805 to run task
[2023-05-31T02:23:29.097+0000] {standard_task_runner.py:82} INFO - Running: ['***', 'tasks', 'run', 'captura_dados', 'created_folders_task', 'manual__2023-05-31T02:23:14.458005+00:00', '--job-id', '72', '--raw', '--subdir', 'DAGS_FOLDER/captura_dados.py', '--cfg-path', '/tmp/tmp92rez26r']
[2023-05-31T02:23:29.100+0000] {standard_task_runner.py:83} INFO - Job 72: Subtask created_folders_task
[2023-05-31T02:23:29.222+0000] {task_command.py:388} INFO - Running <TaskInstance: captura_dados.created_folders_task manual__2023-05-31T02:23:14.458005+00:00 [running]> on host 5219a5ad576c
[2023-05-31T02:23:29.447+0000] {taskinstance.py:1509} INFO - Exporting the following env vars:
AIRFLOW_CTX_DAG_EMAIL=test@test.com
AIRFLOW_CTX_DAG_OWNER=***
AIRFLOW_CTX_DAG_ID=captura_dados
AIRFLOW_CTX_TASK_ID=created_folders_task
AIRFLOW_CTX_EXECUTION_DATE=2023-05-31T02:23:14.458005+00:00
AIRFLOW_CTX_TRY_NUMBER=2
AIRFLOW_CTX_DAG_RUN_ID=manual__2023-05-31T02:23:14.458005+00:00
[2023-05-31T02:23:29.449+0000] {logging_mixin.py:137} INFO - Pasta data j√° existe!
[2023-05-31T02:23:29.459+0000] {taskinstance.py:1768} ERROR - Task failed with exception
Traceback (most recent call last):
  File "/home/airflow/.local/lib/python3.7/site-packages/airflow/operators/python.py", line 175, in execute
    return_value = self.execute_callable()
  File "/home/airflow/.local/lib/python3.7/site-packages/airflow/operators/python.py", line 192, in execute_callable
    return self.python_callable(*self.op_args, **self.op_kwargs)
  File "/opt/airflow/dags/captura_dados.py", line 39, in created_folders
    os.makedirs(diretorio)
  File "/usr/local/lib/python3.7/os.py", line 213, in makedirs
    makedirs(head, exist_ok=exist_ok)
  File "/usr/local/lib/python3.7/os.py", line 213, in makedirs
    makedirs(head, exist_ok=exist_ok)
  File "/usr/local/lib/python3.7/os.py", line 213, in makedirs
    makedirs(head, exist_ok=exist_ok)
  [Previous line repeated 1 more time]
  File "/usr/local/lib/python3.7/os.py", line 223, in makedirs
    mkdir(name, mode)
PermissionError: [Errno 13] Permission denied: '/home/michel'
[2023-05-31T02:23:29.473+0000] {taskinstance.py:1323} INFO - Marking task as FAILED. dag_id=captura_dados, task_id=created_folders_task, execution_date=20230531T022314, start_date=20230531T022329, end_date=20230531T022329
[2023-05-31T02:23:29.492+0000] {standard_task_runner.py:105} ERROR - Failed to execute job 72 for task created_folders_task ([Errno 13] Permission denied: '/home/michel'; 2805)
[2023-05-31T02:23:29.531+0000] {local_task_job.py:208} INFO - Task exited with return code 1
[2023-05-31T02:23:29.550+0000] {taskinstance.py:2578} INFO - 0 downstream tasks scheduled from follow-on schedule check
