[2023-05-28T00:44:48.506+0000] {taskinstance.py:1083} INFO - Dependencies all met for <TaskInstance: captura_dados.verifica_arquivos_task manual__2023-05-28T00:23:39.334708+00:00 [queued]>
[2023-05-28T00:44:48.516+0000] {taskinstance.py:1083} INFO - Dependencies all met for <TaskInstance: captura_dados.verifica_arquivos_task manual__2023-05-28T00:23:39.334708+00:00 [queued]>
[2023-05-28T00:44:48.516+0000] {taskinstance.py:1279} INFO - 
--------------------------------------------------------------------------------
[2023-05-28T00:44:48.516+0000] {taskinstance.py:1280} INFO - Starting attempt 1 of 2
[2023-05-28T00:44:48.517+0000] {taskinstance.py:1281} INFO - 
--------------------------------------------------------------------------------
[2023-05-28T00:44:48.532+0000] {taskinstance.py:1300} INFO - Executing <Task(PythonOperator): verifica_arquivos_task> on 2023-05-28 00:23:39.334708+00:00
[2023-05-28T00:44:48.537+0000] {standard_task_runner.py:55} INFO - Started process 115 to run task
[2023-05-28T00:44:48.541+0000] {standard_task_runner.py:82} INFO - Running: ['***', 'tasks', 'run', 'captura_dados', 'verifica_arquivos_task', 'manual__2023-05-28T00:23:39.334708+00:00', '--job-id', '346', '--raw', '--subdir', 'DAGS_FOLDER/captura_dados.py', '--cfg-path', '/tmp/tmpiqw5b19b']
[2023-05-28T00:44:48.541+0000] {standard_task_runner.py:83} INFO - Job 346: Subtask verifica_arquivos_task
[2023-05-28T00:44:48.614+0000] {task_command.py:388} INFO - Running <TaskInstance: captura_dados.verifica_arquivos_task manual__2023-05-28T00:23:39.334708+00:00 [running]> on host 8c251d475d4b
[2023-05-28T00:44:48.723+0000] {taskinstance.py:1509} INFO - Exporting the following env vars:
AIRFLOW_CTX_DAG_EMAIL=test@test.com
AIRFLOW_CTX_DAG_OWNER=***
AIRFLOW_CTX_DAG_ID=captura_dados
AIRFLOW_CTX_TASK_ID=verifica_arquivos_task
AIRFLOW_CTX_EXECUTION_DATE=2023-05-28T00:23:39.334708+00:00
AIRFLOW_CTX_TRY_NUMBER=1
AIRFLOW_CTX_DAG_RUN_ID=manual__2023-05-28T00:23:39.334708+00:00
[2023-05-28T00:44:48.724+0000] {taskinstance.py:1768} ERROR - Task failed with exception
Traceback (most recent call last):
  File "/home/airflow/.local/lib/python3.7/site-packages/airflow/operators/python.py", line 175, in execute
    return_value = self.execute_callable()
  File "/home/airflow/.local/lib/python3.7/site-packages/airflow/operators/python.py", line 192, in execute_callable
    return self.python_callable(*self.op_args, **self.op_kwargs)
TypeError: verifica_arquivos() missing 1 required positional argument: 'diretorio'
[2023-05-28T00:44:48.734+0000] {taskinstance.py:1323} INFO - Marking task as UP_FOR_RETRY. dag_id=captura_dados, task_id=verifica_arquivos_task, execution_date=20230528T002339, start_date=20230528T004448, end_date=20230528T004448
[2023-05-28T00:44:48.748+0000] {standard_task_runner.py:105} ERROR - Failed to execute job 346 for task verifica_arquivos_task (verifica_arquivos() missing 1 required positional argument: 'diretorio'; 115)
[2023-05-28T00:44:48.797+0000] {local_task_job.py:208} INFO - Task exited with return code 1
[2023-05-28T00:44:48.823+0000] {taskinstance.py:2578} INFO - 0 downstream tasks scheduled from follow-on schedule check
